<?xml version="1.0"?>
<robot name="humanoid_leg" xmlns:xacro="http://ros.org/wiki/xacro">

  <link name="base_link">
    <visual><geometry><box size="0.1 0.1 0.05"/></geometry></visual>
  </link>

  <link name="upper_leg">
    <visual><geometry><box size="0.05 0.05 0.2"/></geometry></visual>
  </link>

  <joint name="hip_joint" type="continuous">
    <parent link="base_link"/>
    <child link="upper_leg"/>
    <origin xyz="0 0 0.05" rpy="0 0 0"/>
    <axis xyz="0 0 1"/>
  </joint>

  <link name="lower_leg">
    <visual><geometry><box size="0.05 0.05 0.2"/></geometry></visual>
  </link>

  <joint name="knee_joint" type="continuous">
    <parent link="upper_leg"/>
    <child link="lower_leg"/>
    <origin xyz="0 0 -0.2" rpy="0 0 0"/>
    <axis xyz="0 0 1"/>
  </joint>

  <link name="foot">
    <visual><geometry><box size="0.05 0.05 0.05"/></geometry></visual>
  </link>

  <joint name="ankle_joint" type="continuous">
    <parent link="lower_leg"/>
    <child link="foot"/>
    <origin xyz="0 0 -0.2" rpy="0 0 0"/>
    <axis xyz="0 0 1"/>
  </joint>

</robot>

