<robot name="humanoid_leg">

  <link name="base_link">
    <visual>
      <geometry>
        <cylinder length="0.05" radius="0.05"/>
      </geometry>
      <origin xyz="0 0 0" rpy="0 0 0"/>
    </visual>
  </link>

  <joint name="hip_joint" type="revolute">
    <parent link="base_link"/>
    <child link="thigh"/>
    <origin xyz="0 0 0.1" rpy="0 0 0"/>
    <axis xyz="1 0 0"/>
    <limit lower="-1.57" upper="1.57" effort="10" velocity="1"/>
  </joint>

  <link name="thigh">
    <visual>
      <geometry>
        <cylinder length="0.2" radius="0.04"/>
      </geometry>
      <origin xyz="0 0 -0.1" rpy="0 0 0"/>
    </visual>
  </link>

  <joint name="knee_joint" type="revolute">
    <parent link="thigh"/>
    <child link="shin"/>
    <origin xyz="0 0 -0.2" rpy="0 0 0"/>
    <axis xyz="1 0 0"/>
    <limit lower="-1.57" upper="1.57" effort="10" velocity="1"/>
  </joint>

  <link name="shin">
    <visual>
      <geometry>
        <cylinder length="0.2" radius="0.035"/>
      </geometry>
      <origin xyz="0 0 -0.1" rpy="0 0 0"/>
    </visual>
  </link>

</robot>

